{
  "comments": [
    {
      "unresolved": false,
      "key": {
        "uuid": "80cb2bfe_29134578",
        "filename": "/PATCHSET_LEVEL",
        "patchSetId": 8
      },
      "lineNbr": 0,
      "author": {
        "id": 24824
      },
      "writtenOn": "2022-09-13T20:15:26Z",
      "side": 1,
      "message": "recheck",
      "revId": "e0096394933230797b3d7dc3b377e691211fc45f",
      "serverId": "4a232e18-c5a9-48ee-94c0-e04e7cca6543"
    },
    {
      "unresolved": false,
      "key": {
        "uuid": "bef08677_c659ad98",
        "filename": "/PATCHSET_LEVEL",
        "patchSetId": 8
      },
      "lineNbr": 0,
      "author": {
        "id": 13686
      },
      "writtenOn": "2022-09-14T06:43:02Z",
      "side": 1,
      "message": "https://github.com/openstack-charmers/zaza-openstack-tests/pull/909",
      "revId": "e0096394933230797b3d7dc3b377e691211fc45f",
      "serverId": "4a232e18-c5a9-48ee-94c0-e04e7cca6543"
    },
    {
      "unresolved": false,
      "key": {
        "uuid": "ca73de5d_402ae84d",
        "filename": "/PATCHSET_LEVEL",
        "patchSetId": 8
      },
      "lineNbr": 0,
      "author": {
        "id": 13686
      },
      "writtenOn": "2022-09-14T07:10:25Z",
      "side": 1,
      "message": "charm-recheck",
      "revId": "e0096394933230797b3d7dc3b377e691211fc45f",
      "serverId": "4a232e18-c5a9-48ee-94c0-e04e7cca6543"
    },
    {
      "unresolved": false,
      "key": {
        "uuid": "7c5cc950_3114ad46",
        "filename": "/PATCHSET_LEVEL",
        "patchSetId": 8
      },
      "lineNbr": 0,
      "author": {
        "id": 13686
      },
      "writtenOn": "2022-09-14T09:24:43Z",
      "side": 1,
      "message": "2022-09-14 08:49:32.182909 | focal-medium | novaclient.exceptions.ClientException: Unexpected API Error. Please report this at http://bugs.launchpad.net/nova/ and attach the Nova API log if possible.\n2022-09-14 08:49:32.182933 | focal-medium | \u003cclass \u0027nova.exception_Remote.PortBindingFailed_Remote\u0027\u003e (HTTP 500) (Request-ID: req-5d341516-2968-4bba-9674-8daede953f91)\n\nCI infra issue",
      "revId": "e0096394933230797b3d7dc3b377e691211fc45f",
      "serverId": "4a232e18-c5a9-48ee-94c0-e04e7cca6543"
    },
    {
      "unresolved": false,
      "key": {
        "uuid": "76fabe3f_dc62cac2",
        "filename": "/PATCHSET_LEVEL",
        "patchSetId": 8
      },
      "lineNbr": 0,
      "author": {
        "id": 13686
      },
      "writtenOn": "2022-09-14T09:24:53Z",
      "side": 1,
      "message": "charm-recheck",
      "revId": "e0096394933230797b3d7dc3b377e691211fc45f",
      "serverId": "4a232e18-c5a9-48ee-94c0-e04e7cca6543"
    },
    {
      "unresolved": false,
      "key": {
        "uuid": "4b7aa4dd_48cc43b4",
        "filename": "/PATCHSET_LEVEL",
        "patchSetId": 8
      },
      "lineNbr": 0,
      "author": {
        "id": 24824
      },
      "writtenOn": "2022-09-14T12:46:22Z",
      "side": 1,
      "message": "2022-09-14 10:14:48.751565 | focal-medium | 2022-09-14 10:14:48 [ERROR] Model default_alias (zaza-af4f94bc5dc2)\n2022-09-14 10:14:49.984119 | focal-medium | Traceback (most recent call last):\n2022-09-14 10:14:49.984202 | focal-medium |   File \"/home/ubuntu/src/review.opendev.org/x/charm-ovn-chassis/src/.tox/func-target/lib/python3.8/site-packages/urllib3/connectionpool.py\", line 703, in urlopen\n2022-09-14 10:14:49.984238 | focal-medium |     httplib_response \u003d self._make_request(\n2022-09-14 10:14:49.984251 | focal-medium |   File \"/home/ubuntu/src/review.opendev.org/x/charm-ovn-chassis/src/.tox/func-target/lib/python3.8/site-packages/urllib3/connectionpool.py\", line 449, in _make_request\n2022-09-14 10:14:49.984282 | focal-medium |     six.raise_from(e, None)\n2022-09-14 10:14:49.984294 | focal-medium |   File \"\u003cstring\u003e\", line 3, in raise_from\n2022-09-14 10:14:49.984306 | focal-medium |   File \"/home/ubuntu/src/review.opendev.org/x/charm-ovn-chassis/src/.tox/func-target/lib/python3.8/site-packages/urllib3/connectionpool.py\", line 444, in _make_request\n2022-09-14 10:14:49.984318 | focal-medium |     httplib_response \u003d conn.getresponse()\n2022-09-14 10:14:49.984332 | focal-medium |   File \"/usr/lib/python3.8/http/client.py\", line 1348, in getresponse\n2022-09-14 10:14:49.984348 | focal-medium |     response.begin()\n2022-09-14 10:14:49.984359 | focal-medium |   File \"/usr/lib/python3.8/http/client.py\", line 316, in begin\n2022-09-14 10:14:49.984386 | focal-medium |     version, status, reason \u003d self._read_status()\n2022-09-14 10:14:49.984399 | focal-medium |   File \"/usr/lib/python3.8/http/client.py\", line 285, in _read_status\n2022-09-14 10:14:49.984410 | focal-medium |     raise RemoteDisconnected(\"Remote end closed connection without\"\n2022-09-14 10:14:49.984420 | focal-medium | http.client.RemoteDisconnected: Remote end closed connection without response\n",
      "revId": "e0096394933230797b3d7dc3b377e691211fc45f",
      "serverId": "4a232e18-c5a9-48ee-94c0-e04e7cca6543"
    },
    {
      "unresolved": false,
      "key": {
        "uuid": "1eab8e9a_1a546ff0",
        "filename": "/PATCHSET_LEVEL",
        "patchSetId": 8
      },
      "lineNbr": 0,
      "author": {
        "id": 24824
      },
      "writtenOn": "2022-09-14T12:46:35Z",
      "side": 1,
      "message": "recheck",
      "revId": "e0096394933230797b3d7dc3b377e691211fc45f",
      "serverId": "4a232e18-c5a9-48ee-94c0-e04e7cca6543"
    },
    {
      "unresolved": false,
      "key": {
        "uuid": "46e99a4a_6004903a",
        "filename": "/PATCHSET_LEVEL",
        "patchSetId": 8
      },
      "lineNbr": 0,
      "author": {
        "id": 24824
      },
      "writtenOn": "2022-09-14T19:12:23Z",
      "side": 1,
      "message": "recheck",
      "revId": "e0096394933230797b3d7dc3b377e691211fc45f",
      "serverId": "4a232e18-c5a9-48ee-94c0-e04e7cca6543"
    },
    {
      "unresolved": false,
      "key": {
        "uuid": "c6cc9c75_3bf646de",
        "filename": "/PATCHSET_LEVEL",
        "patchSetId": 8
      },
      "lineNbr": 0,
      "author": {
        "id": 24824
      },
      "writtenOn": "2022-09-14T22:16:41Z",
      "side": 1,
      "message": "recheck",
      "revId": "e0096394933230797b3d7dc3b377e691211fc45f",
      "serverId": "4a232e18-c5a9-48ee-94c0-e04e7cca6543"
    },
    {
      "unresolved": false,
      "key": {
        "uuid": "37f1ecd1_16848357",
        "filename": "/PATCHSET_LEVEL",
        "patchSetId": 8
      },
      "lineNbr": 0,
      "author": {
        "id": 24824
      },
      "writtenOn": "2022-09-15T00:02:02Z",
      "side": 1,
      "message": "Filed https://bugs.launchpad.net/juju/+bug/1989629 regarding the spurious hook failures.",
      "revId": "e0096394933230797b3d7dc3b377e691211fc45f",
      "serverId": "4a232e18-c5a9-48ee-94c0-e04e7cca6543"
    },
    {
      "unresolved": false,
      "key": {
        "uuid": "3808dbe7_3dca6260",
        "filename": "/PATCHSET_LEVEL",
        "patchSetId": 8
      },
      "lineNbr": 0,
      "author": {
        "id": 24824
      },
      "writtenOn": "2022-09-15T08:15:05Z",
      "side": 1,
      "message": "Now it\u0027s something else:\n\n2022-09-14 23:47:20 ERROR unit.ovn-chassis/0.juju-log server.go:316 Hook error:\nTraceback (most recent call last):\n  File \"/var/lib/juju/agents/unit-ovn-chassis-0/.venv/lib/python3.8/site-packages/charms/reactive/__init__.py\", line 74, in main\n    bus.dispatch(restricted\u003drestricted_mode)\n  File \"/var/lib/juju/agents/unit-ovn-chassis-0/.venv/lib/python3.8/site-packages/charms/reactive/bus.py\", line 390, in dispatch\n    _invoke(other_handlers)\n  File \"/var/lib/juju/agents/unit-ovn-chassis-0/.venv/lib/python3.8/site-packages/charms/reactive/bus.py\", line 359, in _invoke\n    handler.invoke()\n  File \"/var/lib/juju/agents/unit-ovn-chassis-0/.venv/lib/python3.8/site-packages/charms/reactive/bus.py\", line 181, in invoke\n    self._action(*args)\n  File \"/var/lib/juju/agents/unit-ovn-chassis-0/charm/reactive/ovn_chassis_charm_handlers.py\", line 91, in configure_ovs\n    charm_instance.configure_ovs(\n  File \"/var/lib/juju/agents/unit-ovn-chassis-0/charm/lib/charms/ovn_charm.py\", line 178, in configure_ovs\n    super().configure_ovs(sb_conn, mlockall_changed)\n  File \"/var/lib/juju/agents/unit-ovn-chassis-0/charm/lib/charms/ovn_charm.py\", line 1037, in configure_ovs\n    self.configure_ovs_hw_offload() | self.configure_ovs_dpdk())\n  File \"/var/lib/juju/agents/unit-ovn-chassis-0/charm/lib/charms/ovn_charm.py\", line 918, in configure_ovs_dpdk\n    self.dpdk_eal_allow_devices(dpdk_context.devices())\n  File \"/var/lib/juju/agents/unit-ovn-chassis-0/charm/lib/charms/ovn_charm.py\", line 884, in dpdk_eal_allow_devices\n    if ch_core.host.cmp_pkgrevno(\u0027dpdk\u0027, \u002720.11.3\u0027) \u003e\u003d 0:\n  File \"/var/lib/juju/agents/unit-ovn-chassis-0/.venv/lib/python3.8/site-packages/charmhelpers/core/host_factory/ubuntu.py\", line 110, in cmp_pkgrevno\n    return apt_pkg.version_compare(current_ver.ver_str, revno)\nAttributeError: \u0027NoneType\u0027 object has no attribute \u0027ver_str\u0027",
      "revId": "e0096394933230797b3d7dc3b377e691211fc45f",
      "serverId": "4a232e18-c5a9-48ee-94c0-e04e7cca6543"
    },
    {
      "unresolved": false,
      "key": {
        "uuid": "20d69927_5ca06af4",
        "filename": "/PATCHSET_LEVEL",
        "patchSetId": 8
      },
      "lineNbr": 0,
      "author": {
        "id": 24824
      },
      "writtenOn": "2022-09-15T10:56:03Z",
      "side": 1,
      "message": "Looks like the issue is intermittent as the focal-xena test ran successfully on my env:\n\nhttps://paste.ubuntu.com/p/ShY3zCZWWx/.\n\nI\u0027ve seen a similar error in a different bug already some time ago:\n\nhttps://bugs.launchpad.net/charm-rabbitmq-server/+bug/1879378/comments/1\n\ncurrent_ver is None if a package is not installed:\n\nhttps://apt-team.pages.debian.net/python-apt/library/apt_pkg.html#apt_pkg.Package.current_ver",
      "parentUuid": "3808dbe7_3dca6260",
      "revId": "e0096394933230797b3d7dc3b377e691211fc45f",
      "serverId": "4a232e18-c5a9-48ee-94c0-e04e7cca6543"
    }
  ]
}